<?xml version="1.0"?>
<robot name="ur5e" xmlns:xacro="https://ros.org/wiki/xacro">

<!-- ROBOT LINK AND CONSTRUCTION PARAMETERS -->
<!-- The following parameters are obtained from official and unofficial site -->
<!-- https://github.com/ros-industrial/universal_robot -->

    <xacro:property name="shoulder_length" value="0.163"/>
    <xacro:property name="upperarm_length" value="0.425"/>
    <xacro:property name="forearm_length" value="0.3922"/>
    <xacro:property name="wrist1_length" value="0.127"/>
    <xacro:property name="wrist2_length" value="0.0997"/>
    <xacro:property name="wrist3_length" value="0.0996"/>

    <xacro:property name="base_mass" value="4.0"/>
    <xacro:property name="shoulder_mass" value="3.761"/>
    <xacro:property name="upperarm_mass" value="8.058"/>
    <xacro:property name="forearm_mass" value="2.846"/>
    <xacro:property name="wrist1_mass" value="1.37"/>
    <xacro:property name="wrist2_mass" value="1.3"/>
    <xacro:property name="wrist3_mass" value="0.365"/>

    <xacro:property name="shoulder_radius" value="0.06"/>
    <xacro:property name="upperarm_radius" value="0.054"/>
    <xacro:property name="forearm_radius" value="0.040"/>
    <xacro:property name="wrist_radius" value="0.045"/>

    <xacro:property name="shoulder_offset" value="0.138"/>
    <xacro:property name="elbow_offset" value="-0.131"/>
<!-- END OF PARAMETERS -->

<!-- MACROS -->
    <xacro:macro name="cylinder_inertial" params="radius length mass *origin">
        <inertial>
            <mass value="${mass}" />
            <xacro:insert_block name="origin" />
        <inertia ixx="${0.0833333 * mass * (3 * radius * radius + length * length)}" ixy="0.0" ixz="0.0"
            iyy="${0.0833333 * mass * (3 * radius * radius + length * length)}" iyz="0.0"
            izz="${0.5 * mass * radius * radius}" />
        </inertial>
    </xacro:macro>

    <xacro:macro name="transmission_block" params="joint_trans joint_name joint_motor"> 
        <transmission name="${joint_trans}"> 
            <type>transmission_interface/SimpleTransmission</type> 
            <joint name="${joint_name}"> 
                <hardwareInterface>hardware_interface/PositionJointInterface</hardwareInterface> 
            </joint> 
            <actuator name="${joint_motor}"> 
                <mechanicalReduction>1</mechanicalReduction> 
            </actuator> 
        </transmission> 
   </xacro:macro>

<!-- END OF MACROS -->

<!-- ROBOT LINK AND JOINTS -->
    <link name="world"/>

    <joint name="fixed" type="fixed">
        <!-- <origin xyz="0.0 0.0 0.0" rpy="0.0 0.0 ${-pi}"/> -->
        <parent link="world"/>
        <child link="base_link"/>
    </joint>

    <link name="base_link">
        <xacro:cylinder_inertial radius="0.06" length="0.05" mass="${base_mass}">
            <origin xyz="0.0 0.0 0.0" rpy="0.0 0.0 0.0"/>
        </xacro:cylinder_inertial>
        <visual>
            <origin xyz="0.0 0.0 0.0" rpy="0.0 0.0 0.0"/>
            <geometry>
                <!-- <cylinder radius="0.06" length="0.05"/> -->
                <mesh filename="$(find mmt_robotics)/meshes/ur5e/visual/base.dae" />
            </geometry>
            <material name="">
                <color rgba="1.0 0.0 0.0 1.0"/>
            </material>
        </visual>
        <collision>
            <origin xyz="0.0 0.0 0.0" rpy="0.0 0.0 0.0"/>
            <geometry>
                <!-- <cylinder radius="0.06" length="0.05"/> -->
                <mesh filename="$(find mmt_robotics)/meshes/ur5e/visual/base.stl" />
            </geometry>
        </collision>
    </link>

    <joint name="shoulder_pan" type="revolute">
        <origin xyz="0.0 0.0 ${shoulder_length}" rpy="0.0 0.0 0.0"/>
        <parent link="base_link"/>
        <child link="shoulder_link"/>
        <axis xyz="0 0 1"/>
        <limit lower="${-2.0 * pi}" upper="${2.0 * pi}" effort="150.0" velocity="3.14"/>
        <dynamics damping="0.0" friction="0.0" />
    </joint>

    <link name="shoulder_link">
        <xacro:cylinder_inertial radius="0.06" length="0.15" mass="${shoulder_mass}">
            <origin xyz="0.0 0.0 0.0" rpy="0.0 0.0 0.0"/>
        </xacro:cylinder_inertial>
        <visual>
            <origin xyz="0.0 0.0 0.0" rpy="0.0 0.0 0.0"/>
            <geometry>
                <!-- <cylinder radius="0.06" length="0.15"/> -->
                <mesh filename="$(find mmt_robotics)/meshes/ur5e/visual/shoulder.dae" />
            </geometry>
            <material name="">
                <color rgba="1.0 0.0 0.0 1.0"/>
            </material>
        </visual>
        <collision>
            <origin xyz="0.0 0.0 0.0" rpy="0.0 0.0 0.0"/>
            <geometry>
                <!-- <cylinder radius="0.06" length="0.15"/> -->
                <mesh filename="$(find mmt_robotics)/meshes/ur5e/visual/shoulder.stl" />
            </geometry>
        </collision>
    </link>

    <joint name="shoulder_lift" type="revolute">
        <origin xyz="0.0 ${shoulder_offset} 0.0" rpy="0.0 ${pi/2.0} 0.0"/>
        <parent link="shoulder_link"/>
        <child link="upperarm_link"/>
        <axis xyz="0.0 1.0 0.0"/>
        <limit lower="${-2.0 * pi}" upper="${2.0 * pi}" effort="150.0" velocity="3.14"/>
        <dynamics damping="0.0" friction="0.0" />
    </joint>

    <link name="upperarm_link">
        <xacro:cylinder_inertial radius="0.06" length="${upperarm_length}" mass="${upperarm_mass}">
            <origin xyz="0.0 0.0 0.0" rpy="0.0 0.0 0.0"/>
        </xacro:cylinder_inertial>
        <visual>
            <origin xyz="0.0 0.0 0.0" rpy="0.0 0.0 0.0"/>
            <geometry>
                <!-- <cylinder radius="0.06" length="${upperarm_length}"/> -->
                <mesh filename="$(find mmt_robotics)/meshes/ur5e/visual/upperarm.dae" />
            </geometry>
            <material name="">
                <color rgba="1.0 0.0 0.0 1.0"/>
            </material>
        </visual>
        <collision>
            <origin xyz="0.0 0.0 0.0" rpy="0.0 0.0 0.0"/>
            <geometry>
                <!-- <cylinder radius="0.06" length="${upperarm_length}"/> -->
                <mesh filename="$(find mmt_robotics)/meshes/ur5e/visual/upperarm.stl" />
            </geometry>
        </collision>
    </link>

    <joint name="elbow_joint" type="revolute">
        <origin xyz="0.0 ${elbow_offset} ${upperarm_length}" rpy="0.0 0.0 0.0"/>
        <parent link="upperarm_link"/>
        <child link="forearm_link"/>
        <axis xyz="0.0 1 0.0"/>
        <limit lower="${-pi}" upper="${pi}" effort="150.0" velocity="3.14"/>
        <dynamics damping="0.0" friction="0.0" />
    </joint>

    <link name="forearm_link">
        <xacro:cylinder_inertial radius="${forearm_radius}" length="${forearm_length}" mass="${forearm_mass}">
            <origin xyz="0.0 0.0 0.0" rpy="0.0 0.0 0.0"/>
        </xacro:cylinder_inertial>
        <visual>
            <origin xyz="0.0 0.0 0.0" rpy="0.0 0.0 0.0"/>
            <geometry>
                <!-- <cylinder radius="0.06" length="${forearm_length}"/> -->
                <mesh filename="$(find mmt_robotics)/meshes/ur5e/visual/forearm.dae" />
            </geometry>
            <material name="">
                <color rgba="1.0 0.0 0.0 1.0"/>
            </material>
        </visual>
        <collision>
            <origin xyz="0.0 0.0 0.0" rpy="0.0 0.0 0.0"/>
            <geometry>
                <!-- <cylinder radius="0.06" length="${forearm_length}"/> -->
                <mesh filename="$(find mmt_robotics)/meshes/ur5e/visual/forearm.stl" />
            </geometry>
        </collision>
    </link>

    <joint name="wrist1_joint" type="revolute">
        <origin xyz="0.0 0.0 ${forearm_length}" rpy="0.0 ${pi/2.0} 0.0"/>
        <parent link="forearm_link"/>
        <child link="wrist1_link"/>
        <axis xyz="0.0 1 0.0"/>
        <limit lower="${-2.0*pi}" upper="${2.0*pi}" effort="150.0" velocity="3.14"/>
        <dynamics damping="0.0" friction="0.0" />
    </joint>

   <link name="wrist1_link">
        <xacro:cylinder_inertial radius="0.06" length="0.12" mass="${wrist1_mass}">
            <origin xyz="0.0 0.0 0.0" rpy="0.0 0.0 0.0"/>
        </xacro:cylinder_inertial>
        <visual>
            <origin xyz="0.0 0.0 0.0" rpy="0.0 0.0 0.0"/>
            <geometry>
                <!-- <cylinder radius="0.06" length="0.12"/> -->
                <mesh filename="$(find mmt_robotics)/meshes/ur5e/visual/wrist1.dae" />
            </geometry>
            <material name="">
                <color rgba="1.0 0.0 0.0 1.0"/>
            </material>
        </visual>
        <collision>
            <origin xyz="0.0 0.0 0.0" rpy="0.0 0.0 0.0"/>
            <geometry>
                <!-- <cylinder radius="0.06" length="0.12"/> -->
                <mesh filename="$(find mmt_robotics)/meshes/ur5e/visual/wrist1.stl" />
            </geometry>
        </collision>
    </link>

    <joint name="wrist2_joint" type="revolute">
        <origin xyz="0.0 ${wrist1_length} 0.0" rpy="0.0 0.0 0.0"/>
        <parent link="wrist1_link"/>
        <child link="wrist2_link"/>
        <axis xyz="0.0 0.0 1"/>
        <limit lower="${-2.0*pi}" upper="${2.0*pi}" effort="150.0" velocity="3.14"/>
        <dynamics damping="0.0" friction="0.0" />
    </joint>

   <link name="wrist2_link">
        <xacro:cylinder_inertial radius="0.06" length="0.12" mass="${wrist2_mass}">
            <origin xyz="0.0 0.0 0.0" rpy="0.0 0.0 0.0"/>
        </xacro:cylinder_inertial>
        <visual>
            <origin xyz="0.0 0.0 0.0" rpy="0.0 0.0 0.0"/>
            <geometry>
                <!-- <cylinder radius="0.06" length="0.12"/> -->
                <mesh filename="$(find mmt_robotics)/meshes/ur5e/visual/wrist2.dae" />
            </geometry>
            <material name="">
                <color rgba="1.0 0.0 0.0 1.0"/>
            </material>
        </visual>
        <collision>
            <origin xyz="0.0 0.0 0.0" rpy="0.0 0.0 0.0"/>
            <geometry>
                <!-- <cylinder radius="0.06" length="0.12"/> -->
                <mesh filename="$(find mmt_robotics)/meshes/ur5e/visual/wrist2.stl" />
            </geometry>
        </collision>
    </link>

    <joint name="wrist3_joint" type="revolute">
        <origin xyz="0.0 0.0 ${wrist2_length}" rpy="0.0 0.0 0.0"/>
        <parent link="wrist2_link"/>
        <child link="wrist3_link"/>
        <axis xyz="0.0 1 0.0"/>
        <limit lower="${-2.0*pi}" upper="${2.0*pi}" effort="150.0" velocity="3.14"/>
        <dynamics damping="0.0" friction="0.0" />
    </joint>

   <link name="wrist3_link">
        <xacro:cylinder_inertial radius="0.0375" length="0.0458" mass="${wrist3_mass}">
            <origin xyz="0.0 0.0 0.0" rpy="0.0 0.0 0.0"/>
        </xacro:cylinder_inertial>
        <visual>
            <origin xyz="0.0 0.0 0.0" rpy="0.0 0.0 0.0"/>
            <geometry>
                <!-- <cylinder radius="0.0375" length="0.0458"/> -->
                <mesh filename="$(find mmt_robotics)/meshes/ur5e/visual/wrist3.dae" />
            </geometry>
            <material name="">
                <color rgba="1.0 0.0 0.0 1.0"/>
            </material>
        </visual>
        <collision>
            <origin xyz="0.0 0.0 0.0" rpy="0.0 0.0 0.0"/>
            <geometry>
                <!-- <cylinder radius="0.0375" length="0.0458"/> -->
                <mesh filename="$(find mmt_robotics)/meshes/ur5e/visual/wrist3.stl" />
            </geometry>
        </collision>
    </link>

    <joint name="ee_joint" type="fixed">
        <origin xyz="0.0 ${wrist3_length} 0.0" rpy="0.0 0.0 ${pi/2.0}"/>
        <parent link="wrist3_link"/>
        <child link="ee_link"/>
    </joint>

   <link name="ee_link">
        <collision>
            <origin xyz="0.0 0.0 0.0" rpy="-0.05 0.0 0.0"/>
            <geometry>
                <box size="0.03 0.03 0.03"/>
            </geometry>   
        </collision>
    </link>

<!-- END OF ROBOT LINK AND JOINTS -->
    <gazebo> 
        <plugin name="gazebo_ros_control" filename="libgazebo_ros_control.so"> 
            <robotNamespace>/ur5e</robotNamespace> 
        </plugin> 
    </gazebo>

    <xacro:transmission_block joint_trans="shoulder_pan_trans" joint_name="shoulder_pan" joint_motor="shoulder_pan_motor"/>
    <xacro:transmission_block joint_trans="shoulder_lift_trans" joint_name="shoulder_lift" joint_motor="shoulder_lift_motor"/>
    <xacro:transmission_block joint_trans="elbow_joint_trans" joint_name="elbow_joint" joint_motor="elbow_joint_motor"/>
    <xacro:transmission_block joint_trans="wrist1_joint_trans" joint_name="wrist1_joint" joint_motor="wrist1_joint_motor"/>
    <xacro:transmission_block joint_trans="wrist2_joint_trans" joint_name="wrist2_joint" joint_motor="wrist2_joint_motor"/>
    <xacro:transmission_block joint_trans="wrist3_joint_trans" joint_name="wrist3_joint" joint_motor="wrist3_joint_motor"/>

    <gazebo reference="base_link">
        <!-- <selfCollide>true</selfCollide> -->
        <material>Gazebo/White</material>
    </gazebo>
    <gazebo reference="shoulder_link">
        <!-- <selfCollide>true</selfCollide> -->
        <material>Gazebo/Red</material>
    </gazebo>
    <gazebo reference="upperarm_link">
        <!-- <selfCollide>true</selfCollide> -->
        <material>Gazebo/White</material>
    </gazebo>
    <gazebo reference="wrist1_link">
        <!-- <selfCollide>true</selfCollide> -->
        <material>Gazebo/Red</material>
    </gazebo>
    <gazebo reference="wrist2_link">
        <!-- <selfCollide>true</selfCollide> -->
        <material>Gazebo/White</material>
    </gazebo>
    <gazebo reference="wrist3_link">
        <!-- <selfCollide>true</selfCollide> -->
        <material>Gazebo/Red</material>
    </gazebo>

</robot>