<?xml version="1.0" ?>
<!-- =================================================================================== -->
<!-- |    This document was autogenerated by xacro from src/mmt_robotics/urdf/ur5e.urdf.xacro | -->
<!-- |    EDITING THIS FILE BY HAND IS NOT RECOMMENDED                                 | -->
<!-- =================================================================================== -->
<robot name="ur5e">
  <!-- ROBOT LINK AND CONSTRUCTION PARAMETERS -->
  <!-- The following parameters are obtained from official and unofficial site -->
  <!-- https://github.com/ros-industrial/universal_robot -->
  <!-- END OF PARAMETERS -->
  <!-- END OF MACROS -->
  <!-- ROBOT LINK AND JOINTS -->
  <link name="world"/>
  <joint name="fixed" type="fixed">
    <!-- <origin xyz="0.0 0.0 0.0" rpy="0.0 0.0 ${-pi}"/> -->
    <parent link="world"/>
    <child link="base_link"/>
  </joint>
  <link name="base_link">
    <inertial>
      <mass value="4.0"/>
      <origin rpy="0.0 0.0 0.0" xyz="0.0 0.0 0.025"/>
      <inertia ixx="0.00443333156" ixy="0.0" ixz="0.0" iyy="0.00443333156" iyz="0.0" izz="0.0072"/>
    </inertial>
    <visual>
      <origin rpy="0.0 0.0 0.0" xyz="0.0 0.0 0.025"/>
      <geometry>
        <cylinder length="0.05" radius="0.06"/>
      </geometry>
      <material name="">
        <color rgba="1.0 0.0 0.0 1.0"/>
      </material>
    </visual>
    <collision>
      <origin rpy="0.0 0.0 0.0" xyz="0.0 0.0 0.025"/>
      <geometry>
        <cylinder length="0.05" radius="0.06"/>
      </geometry>
    </collision>
  </link>
  <joint name="shoulder_pan" type="revolute">
    <origin rpy="0.0 0.0 0.0" xyz="0.0 0.0 0.163"/>
    <parent link="base_link"/>
    <child link="shoulder_link"/>
    <axis xyz="0 0 1"/>
    <limit effort="150.0" lower="-6.283185307179586" upper="6.283185307179586" velocity="3.14"/>
    <dynamics damping="0.0" friction="0.0"/>
  </joint>
  <link name="shoulder_link">
    <inertial>
      <mass value="3.761"/>
      <origin rpy="0.0 0.0 0.0" xyz="0.0 0.0 0.0"/>
      <inertia ixx="0.0117120627318397" ixy="0.0" ixz="0.0" iyy="0.0117120627318397" iyz="0.0" izz="0.006769799999999999"/>
    </inertial>
    <visual>
      <origin rpy="0.0 0.0 0.0" xyz="0.0 0.0 0.0"/>
      <geometry>
        <cylinder length="0.163" radius="0.06"/>
      </geometry>
      <material name="">
        <color rgba="1.0 0.0 0.0 1.0"/>
      </material>
    </visual>
    <collision>
      <origin rpy="0.0 0.0 0.0" xyz="0.0 0.0 0.0"/>
      <geometry>
        <cylinder length="0.163" radius="0.06"/>
      </geometry>
    </collision>
  </link>
  <joint name="shoulder_lift" type="revolute">
    <origin rpy="0.0 1.5707963267948966 0.0" xyz="0.0 0.138 0.0"/>
    <parent link="shoulder_link"/>
    <child link="upperarm_link"/>
    <axis xyz="0.0 1.0 0.0"/>
    <limit effort="150.0" lower="-6.283185307179586" upper="6.283185307179586" velocity="3.14"/>
    <dynamics damping="0.0" friction="0.0"/>
  </joint>
  <link name="upperarm_link">
    <inertial>
      <mass value="8.058"/>
      <origin rpy="0.0 0.0 0.0" xyz="0.0 0.0 0.2125"/>
      <inertia ixx="0.12716391863441218" ixy="0.0" ixz="0.0" iyy="0.12716391863441218" iyz="0.0" izz="0.011748564"/>
    </inertial>
    <visual>
      <origin rpy="0.0 0.0 0.0" xyz="0.0 0.0 0.2125"/>
      <geometry>
        <cylinder length="0.425" radius="0.054"/>
      </geometry>
      <material name="">
        <color rgba="1.0 0.0 0.0 1.0"/>
      </material>
    </visual>
    <collision>
      <origin rpy="0.0 0.0 0.0" xyz="0.0 0.0 0.2125"/>
      <geometry>
        <cylinder length="0.425" radius="0.054"/>
      </geometry>
    </collision>
  </link>
  <joint name="elbow_joint" type="revolute">
    <origin rpy="0.0 0.0 0.0" xyz="0.0 -0.131 0.425"/>
    <parent link="upperarm_link"/>
    <child link="forearm_link"/>
    <axis xyz="0.0 1 0.0"/>
    <limit effort="150.0" lower="-3.141592653589793" upper="3.141592653589793" velocity="3.14"/>
    <dynamics damping="0.0" friction="0.0"/>
  </joint>
  <link name="forearm_link">
    <inertial>
      <mass value="2.846"/>
      <origin rpy="0.0 0.0 0.0" xyz="0.0 0.0 0.1961"/>
      <inertia ixx="0.03761956083883631" ixy="0.0" ixz="0.0" iyy="0.03761956083883631" iyz="0.0" izz="0.0022768000000000003"/>
    </inertial>
    <visual>
      <origin rpy="0.0 0.0 0.0" xyz="0.0 0.0 0.1961"/>
      <geometry>
        <cylinder length="0.3922" radius="0.04"/>
      </geometry>
      <material name="">
        <color rgba="1.0 0.0 0.0 1.0"/>
      </material>
    </visual>
    <collision>
      <origin rpy="0.0 0.0 0.0" xyz="0.0 0.0 0.1961"/>
      <geometry>
        <cylinder length="0.3922" radius="0.04"/>
      </geometry>
    </collision>
  </link>
  <joint name="wrist1_joint" type="revolute">
    <origin rpy="0.0 1.5707963267948966 0.0" xyz="0.0 0.0 0.3922"/>
    <parent link="forearm_link"/>
    <child link="wrist1_link"/>
    <axis xyz="0.0 1 0.0"/>
    <limit effort="150.0" lower="-6.283185307179586" upper="6.283185307179586" velocity="3.14"/>
    <dynamics damping="0.0" friction="0.0"/>
  </joint>
  <link name="wrist1_link">
    <inertial>
      <mass value="1.37"/>
      <origin rpy="0.0 0.0 0.0" xyz="0.0 0.127 0.0"/>
      <inertia ixx="0.0025349556526840004" ixy="0.0" ixz="0.0" iyy="0.0025349556526840004" iyz="0.0" izz="0.0013871250000000001"/>
    </inertial>
    <visual>
      <origin rpy="0.0 0.0 0.0" xyz="0.0 0.127 0.0"/>
      <geometry>
        <cylinder length="0.127" radius="0.045"/>
      </geometry>
      <material name="">
        <color rgba="1.0 0.0 0.0 1.0"/>
      </material>
    </visual>
    <collision>
      <origin rpy="0.0 0.0 0.0" xyz="0.0 0.127 0.0"/>
      <geometry>
        <cylinder length="0.127" radius="0.045"/>
      </geometry>
    </collision>
  </link>
  <joint name="wrist2_joint" type="revolute">
    <origin rpy="0.0 0.0 0.0" xyz="0.0 0.127 0.0"/>
    <parent link="wrist1_link"/>
    <child link="wrist2_link"/>
    <axis xyz="0.0 0.0 1"/>
    <limit effort="150.0" lower="-6.283185307179586" upper="6.283185307179586" velocity="3.14"/>
    <dynamics damping="0.0" friction="0.0"/>
  </joint>
  <link name="wrist2_link">
    <inertial>
      <mass value="1.3"/>
      <origin rpy="0.0 0.0 0.0" xyz="0.0 0.0 0.0997"/>
      <inertia ixx="0.0017349673893460999" ixy="0.0" ixz="0.0" iyy="0.0017349673893460999" iyz="0.0" izz="0.00131625"/>
    </inertial>
    <visual>
      <origin rpy="0.0 0.0 0.0" xyz="0.0 0.0 0.0997"/>
      <geometry>
        <cylinder length="0.0997" radius="0.045"/>
      </geometry>
      <material name="">
        <color rgba="1.0 0.0 0.0 1.0"/>
      </material>
    </visual>
    <collision>
      <origin rpy="0.0 0.0 0.0" xyz="0.0 0.0 0.0997"/>
      <geometry>
        <cylinder length="0.0997" radius="0.045"/>
      </geometry>
    </collision>
  </link>
  <joint name="wrist3_joint" type="revolute">
    <origin rpy="0.0 0.0 0.0" xyz="0.0 0.0 0.0997"/>
    <parent link="wrist2_link"/>
    <child link="wrist3_link"/>
    <axis xyz="0.0 1 0.0"/>
    <limit effort="150.0" lower="-6.283185307179586" upper="6.283185307179586" velocity="3.14"/>
    <dynamics damping="0.0" friction="0.0"/>
  </joint>
  <link name="wrist3_link">
    <inertial>
      <mass value="0.365"/>
      <origin rpy="1.5707963267948966 0.0 0.0" xyz="0.0 0.0771 0.0"/>
      <inertia ixx="0.00048651925539222" ixy="0.0" ixz="0.0" iyy="0.00048651925539222" iyz="0.0" izz="0.00036956249999999994"/>
    </inertial>
    <visual>
      <origin rpy="1.5707963267948966 0.0 0.0" xyz="0.0 0.0771 0.0"/>
      <geometry>
        <cylinder length="0.0996" radius="0.045"/>
      </geometry>
      <material name="">
        <color rgba="1.0 0.0 0.0 1.0"/>
      </material>
    </visual>
    <collision>
      <origin rpy="1.5707963267948966 0.0 0.0" xyz="0.0 0.0771 0.0"/>
      <geometry>
        <cylinder length="0.0996" radius="0.045"/>
      </geometry>
    </collision>
  </link>
  <joint name="ee_joint" type="fixed">
    <origin rpy="0.0 0.0 1.5707963267948966" xyz="0.0 0.0996 0.0"/>
    <parent link="wrist3_link"/>
    <child link="ee_link"/>
  </joint>
  <link name="ee_link">
    <collision>
      <origin rpy="-0.05 0.0 0.0" xyz="0.0 0.0 0.0"/>
      <geometry>
        <box size="0.03 0.03 0.03"/>
      </geometry>
    </collision>
  </link>
  <!-- END OF ROBOT LINK AND JOINTS -->
  <gazebo>
    <plugin filename="libgazebo_ros_control.so" name="gazebo_ros_control">
      <robotNamespace>/ur5e</robotNamespace>
    </plugin>
  </gazebo>
  <transmission name="shoulder_pan_trans">
    <type>transmission_interface/SimpleTransmission</type>
    <joint name="shoulder_pan">
      <hardwareInterface>hardware_interface/PositionJointInterface</hardwareInterface>
    </joint>
    <actuator name="shoulder_pan_motor">
      <mechanicalReduction>1</mechanicalReduction>
    </actuator>
  </transmission>
  <transmission name="shoulder_lift_trans">
    <type>transmission_interface/SimpleTransmission</type>
    <joint name="shoulder_lift">
      <hardwareInterface>hardware_interface/PositionJointInterface</hardwareInterface>
    </joint>
    <actuator name="shoulder_lift_motor">
      <mechanicalReduction>1</mechanicalReduction>
    </actuator>
  </transmission>
  <transmission name="elbow_joint_trans">
    <type>transmission_interface/SimpleTransmission</type>
    <joint name="elbow_joint">
      <hardwareInterface>hardware_interface/PositionJointInterface</hardwareInterface>
    </joint>
    <actuator name="elbow_joint_motor">
      <mechanicalReduction>1</mechanicalReduction>
    </actuator>
  </transmission>
  <transmission name="wrist1_joint_trans">
    <type>transmission_interface/SimpleTransmission</type>
    <joint name="wrist1_joint">
      <hardwareInterface>hardware_interface/PositionJointInterface</hardwareInterface>
    </joint>
    <actuator name="wrist1_joint_motor">
      <mechanicalReduction>1</mechanicalReduction>
    </actuator>
  </transmission>
  <transmission name="wrist2_joint_trans">
    <type>transmission_interface/SimpleTransmission</type>
    <joint name="wrist2_joint">
      <hardwareInterface>hardware_interface/PositionJointInterface</hardwareInterface>
    </joint>
    <actuator name="wrist2_joint_motor">
      <mechanicalReduction>1</mechanicalReduction>
    </actuator>
  </transmission>
  <transmission name="wrist3_joint_trans">
    <type>transmission_interface/SimpleTransmission</type>
    <joint name="wrist3_joint">
      <hardwareInterface>hardware_interface/PositionJointInterface</hardwareInterface>
    </joint>
    <actuator name="wrist3_joint_motor">
      <mechanicalReduction>1</mechanicalReduction>
    </actuator>
  </transmission>
  <gazebo reference="base_link">
    <!-- <selfCollide>true</selfCollide> -->
    <material>Gazebo/White</material>
  </gazebo>
  <gazebo reference="shoulder_link">
    <!-- <selfCollide>true</selfCollide> -->
    <material>Gazebo/Red</material>
  </gazebo>
  <gazebo reference="upperarm_link">
    <!-- <selfCollide>true</selfCollide> -->
    <material>Gazebo/White</material>
  </gazebo>
  <gazebo reference="wrist1_link">
    <!-- <selfCollide>true</selfCollide> -->
    <material>Gazebo/Red</material>
  </gazebo>
  <gazebo reference="wrist2_link">
    <!-- <selfCollide>true</selfCollide> -->
    <material>Gazebo/White</material>
  </gazebo>
  <gazebo reference="wrist3_link">
    <!-- <selfCollide>true</selfCollide> -->
    <material>Gazebo/Red</material>
  </gazebo>
</robot>

